Workbook
Name _: #REF!
Name __: #REF!
Name ___: #REF!
Name ____: #REF!
Name _____: #REF!
Name ______: #REF!
Name _______: #REF!
Name ________: #REF!
Name _________: #REF!
Name __________: #REF!
Name ___________: #REF!
Name ____________: #REF!
Name _____________: #REF!
Name ______________: #REF!
Name _______________: #REF!
Name ________________: #REF!
Name _________________: #REF!
Name __________________: #REF!
Name ___________________: #REF!
Name ____________________: #REF!
Name _____________________: #REF!
Name A: [1]Data!$A$1
Name aaaaa: #REF!
Name AB: #REF!
Name ABC: #REF!
Name AD: #REF!
Name AS: #REF!
Name B: [2]Data!$A$1
Name BC: #REF!
Name compactées: #REF!
Name Currency: [3]StdInput!$A$5:$A$23
Name Dat: #REF!
Name Divisions: [3]StdInput!$E$21:$H$21
Name DJHGK: #REF!
Name FFFF: #REF!
Name InvestType: [3]StdInput!$D$22:$D$32
Name Print_Area_0: #REF!
Name Print_Area_1: #REF!
Name Print_Area_10: #REF!
Name Print_Area_11: #REF!
Name Print_Area_12: #REF!
Name Print_Area_13: #REF!
Name Print_Area_14: #REF!
Name Print_Area_15: #REF!
Name Print_Area_16: #REF!
Name Print_Area_17: #REF!
Name Print_Area_18: #REF!
Name Print_Area_19: #REF!
Name Print_Area_2: #REF!
Name Print_Area_20: #REF!
Name Print_Area_21: #REF!
Name Print_Area_3: #REF!
Name Print_Area_5: #REF!
Name Print_Area_6: #REF!
Name Print_Area_7: #REF!
Name Print_Area_8: #REF!
Name Print_Area_9: #REF!
Name QQ: #REF!
Name qqqq: #REF!
Name Query2: #REF!

Sheet Summary-HC
B1: 46204
B2: Description | C2: HC Allocation | D2: HC Physicaly req @ line | E2: Assembly Lines | F2: Assembly hrs
A3: Manufacturing | B3: Crew required for BK cable Assembly with supporting crew | C3: ='PN-workout file'!Q3+'PN-workout file'!Q4+'PN-workout file'!Q5+'PN-workout file'!Q6+'PN-workout file'!Q7+'PN-workout file'!Q35+'PN-workout file'!Q37+'PN-workout file'!Q39+'PN-workout file'!Q40+'PN-workout file'!Q41+'PN-workout file'!Q42+'PN-workout file'!Q44+'PN-workout file'!Q45+'Supporting HC details'!H12 -> 1135.1669 | D3: =C3*0.88 -> 998.94691 | F3: Semi-Auto | G3: Manual-Hrs | H3: Insp. & Pack-Hrs | I3: Total | J3: Total Hrs | K3: Per day Hrs | L3: DL % | M3: LR@0.12 | N3: HC/Line
B4: Crew required for ACWHIP with supporting crew | C4: ='PN-workout file'!Q26+'PN-workout file'!Q27+'PN-workout file'!Q28+'PN-workout file'!Q30+'PN-workout file'!Q31+'PN-workout file'!Q32+'PN-workout file'!Q46+'PN-workout file'!Q47+'PN-workout file'!Q48+'PN-workout file'!Q49+'PN-workout file'!Q50+'PN-workout file'!Q51+'PN-workout file'!Q52+'PN-workout file'!Q53+'Supporting HC details'!I12 -> 528.39491 | D4: =C4*0.88 -> 464.98752 | E4: Assembly Line-Core | F4: 2034 | G4: 275741.83 | H4: 93510.476 | I4: =SUM(F4:H4) -> 371286.3 | J4: =I4 -> 371286.3 | K4: =J4/26/7 -> 2040.0346 | L4: =K4/0.88 -> 2318.2212 | M4: =(L4*0.12)+45 -> 323.18654 | N4: =L4+M4 -> 2641.4077
B5: Crew required for Connector with supporting crew | C5: ='PN-workout file'!Q8+'PN-workout file'!Q9+'PN-workout file'!Q10+'PN-workout file'!Q11+'PN-workout file'!Q12+'PN-workout file'!Q13+'PN-workout file'!Q14+'PN-workout file'!Q16+'PN-workout file'!Q17+'PN-workout file'!Q18+'PN-workout file'!Q19+'PN-workout file'!Q20+'PN-workout file'!Q21+'PN-workout file'!Q22+'PN-workout file'!Q25+'Supporting HC details'!J12+PB!M15 -> 329.31295 | D5: =C5*0.88 -> 289.79539 | J5: =I5 -> 0 | K5: =J5/26/7 -> 0 | L5: =K5/0.88 -> 0 | M5: =(L5*0.12) -> 0 | N5: =SUM(L5:M5) -> 0
B6: Crew required in bench | C6: 50 | D6: =C6*0.88 -> 44 | E6: Legacy Power | F6: 1750 | G6: 32307 | H6: 6239 | I6: =SUM(F6:H6) -> 40296 | J6: =I6 -> 40296 | K6: =J6/26/7 -> 221.40659 | L6: =K6/1 -> 221.40659 | M6: =(L6*0.1) -> 22.140659 | N6: =SUM(L6:M6) -> 243.54725
B7: Crew required for EV (Plant 2 & 3) | C7: 199 | D7: =C7*0.88 -> 175.12 | J7: =I7 -> 0 | K7: =J7/26/7 -> 0 | L7: =K7/0.88 -> 0 | M7: =(L7*0.12)+39 -> 39 | N7: =L7+M7 -> 39
B9: Total Crew for Manufacturing | C9: =SUM(C3:C7) -> 2241.8748 | D9: =SUM(D3:D8) -> 1972.8498 | E9: Total Hrs | F9: =SUM(F4:F8) -> 3784 | G9: =SUM(G4:G8) -> 308048.83 | H9: =SUM(H4:H8) -> 99749.476
B10: HC as on June 25th | C10: 2103 | D10: 1860 | F10: =F9+G9+H9 -> 411582.3
B11: Gap | C11: =C10-C9 -> -138.8748 | D11: =D10-D9 -> -112.84982
A12: QA | B12: Crew for QA | C12: 102 | F12: =SUM(F9:H9) -> 411582.3
A13: NPI | B13: Crew for NPI | C13: 156
B14: Total required for July 26 | C14: =SUM(C3:C7)+C12+C13 -> 2499.8748
B15: HC as on June 28th | C15: 2103 | E15: Description | F15: 46199 | G15: 46229 | H15: % of Increase
B16: Balance crew required for production July 26 | C16: =C10-C9 -> -138.8748 | E16: Revenue-($K) | F16: 35200 | G16: 42211 | H16: =(G16-F16)/G16 -> 0.16609415
B17: Revenue planned for July-26 | C17: $40 M | E17: HC | F17: 2012.0434 | G17: =C9 -> 2241.8748 | H17: =(G17-F17)/G17 -> 0.10251748
E18: Revenue/HC ($K) | F18: =F16/F17 -> 17.494652 | G18: =G16/G17 -> 18.828438 | H18: =(G18-F18)/G18 -> 0.070838888

Sheet Sheet8
E4: Capacity Estimate
E5: Bottleneck | F5: Splice crimping
E6: Splice crimp CT | F6: 32
E7: Shift Output | F7: =(3600/F6)*7*0.85/8 -> 83.671875
E8: Daily Output | F8: =F7*3 -> 251.01562

Sheet Sheet1
A3: Row Labels | B3: Sum of Qty Open | C3: Promised Date
A4: 10130664-1RF474HF BK200 IO CABLE ASSY | B4: 3620 | C4: 45560
A5: 10130664-9B0319HLF BARKLIP CABLE ASSEMBLY | B5: 27200 | C5: 25200 in 11th Oct, 2200 in 1st Nov
A6: 10130664-9D0354LF BARKLIP CABLE ASSY-196MM | B6: 2880 | C6: 720 in 9th Oct, 2160 in 18th Oct
A7: 10130664-9D0355LF BARKLIP CABLE ASSY-135MM | B7: 4320 | C7: 720 in 9th Oct, 720 in 9th Oct, 2880 in 8th Nov
A8: 10130664-9D0356LF BARKLIP CABLE ASSY-82MM | B8: 2880 | C8: 720 in 25th Oct, 2160 in 8th Nov
A9: 10130664-9SF463LF BK200 I/O Cable Assembly | B9: 500
A10: 10150562-001 HOUSING RPS04HBR01F | B10: 35000
A11: 10158287-9RF034HF BK 300 CABLE ASSY | B11: 35000 | C11: 10000 in 18th Oct, 25000 in 25th Oct
A12: 10162405-1S2009LF BARKLIP CABLE ASSEMBLY | B12: 52300 | C12: 25K for 4th Oct, 12300 for 18th Oct, 15k for 25th Oct
A13: 10165987-101LF 2POS RAPID LOCK CNR KIT | B13: 20000
A14: (blank)
A15: Grand Total | B15: 183700

Sheet Data (2)
A1: Site | B1: Order | C1: Line | D1: Sold-To | E1: Ship-To | F1: Cust Sort Name | G1: Shipto Sort Name | H1: Purchase Order | I1: Order Date | J1: Customer Item | K1: Item Number | L1: UM | M1: Item Description | N1: HPL | O1: SOP | P1: Item Group | Q1: Required Date | R1: Due Date | S1: Promised Due Date | T1: Lead Time | U1: Available Qty On Hand | V1: Not Avail QOH | W1: QOH (OTHER SITES) | X1: Qty Ordered | Y1: Quantity Allocated | Z1: Quantity Picked | AA1: Qty Shipped | AB1: Quantity Invoiced | AC1: Qty Open | AD1: Price | AE1: Total Line | AF1: Currency | AG1: Actual Exchange Rate | AH1: Base Currency Amount | AI1: Category | AJ1: Modified Date
A2: 49560 | B2: ET105455 | C2: 1 | D2: EACA05 | E2: EACA0503 | F2: AVNET ASIA PTE Ltd | G2: EACA05 | H2: 6208662616 | I2: 45484 | J2: 10162405-1S2009LF | K2: 10162405-1S2009LF | L2: EA | M2: 10162405-1S2009LF BARKLIP CABLE ASSEMBLY | N2: 355 | O2: 20GF | P2: 503BRKCA | Q2: 45569 | R2: 45569 | S2: 45569 | T2: 0 | U2: 4400 | V2: 3308 | W2: 0 | X2: 15000 | Y2: 0 | Z2: 0 | AA2: 0 | AB2: 0 | AC2: 15000 | AD2: 10.86 | AE2: 162900 | AF2: USD | AG2: 84.03361 | AH2: 13574999 | AJ2: 45484
A3: 49560 | B3: ET105395 | C3: 2 | D3: EACA05 | E3: EACA0503 | F3: AVNET ASIA PTE Ltd | G3: EACA05 | H3: 6208588520 | I3: 45447 | J3: 10162405-1S2009LF | K3: 10162405-1S2009LF | L3: EA | M3: 10162405-1S2009LF BARKLIP CABLE ASSEMBLY | N3: 355 | O3: 20GF | P3: 503BRKCA | Q3: 45569 | R3: 45569 | S3: 45569 | T3: 0 | U3: 4400 | V3: 3308 | W3: 0 | X3: 10000 | Y3: 0 | Z3: 0 | AA3: 0 | AB3: 0 | AC3: 10000 | AD3: 10.86 | AE3: 108600 | AF3: USD | AG3: 84.03361 | AH3: 9049999.6 | AJ3: 45447
A4: 49560 | B4: EF101973 | C4: 1 | D4: US10 | E4: 314601 | F4: FCI USA LLC | G4: FCI Electronics | H4: 408701 | I4: 45488 | J4: 10130664-9D0355LF | K4: 10130664-9D0355LF | L4: EA | M4: 10130664-9D0355LF BARKLIP CABLE ASSY-135MM | N4: 355 | O4: 22EF | P4: 503BRKCA | Q4: 45574 | R4: 45574 | S4: 45574 | T4: 0 | U4: 0 | V4: 0 | W4: 0 | X4: 720 | Y4: 0 | Z4: 0 | AA4: 0 | AB4: 0 | AC4: 720 | AD4: 5.6232 | AE4: 4048.7 | AF4: USD | AG4: 84.03361 | AH4: 337391.99
A5: 49560 | B5: EF101973 | C5: 2 | D5: US10 | E5: 314601 | F5: FCI USA LLC | G5: FCI Electronics | H5: 408701 | I5: 45488 | J5: 10130664-9D0354LF | K5: 10130664-9D0354LF | L5: EA | M5: 10130664-9D0354LF BARKLIP CABLE ASSY-196MM | N5: 355 | O5: 22EF | P5: 503BRKCA | Q5: 45574 | R5: 45574 | S5: 45574 | T5: 0 | U5: 312 | V5: 0 | W5: 0 | X5: 720 | Y5: 0 | Z5: 0 | AA5: 0 | AB5: 0 | AC5: 720 | AD5: 5.7816 | AE5: 4162.8 | AF5: USD | AG5: 84.03361 | AH5: 346895.99
A6: 49560 | B6: EF102298 | C6: 1 | D6: CN43 | E6: CN43 | F6: FCI NANTONG LTD. | G6: FCI NANTONG LTD. | H6: IN56CW12 | I6: 45525 | J6: 10165987-101LF | K6: 10165987-101LF | L6: EA | M6: 10165987-101LF 2POS RAPID LOCK CNR KIT | N6: 503 | O6: 22ZS | P6: 5031ASM | Q6: 45569 | R6: 45576 | S6: 45576 | T6: -7 | U6: 0 | V6: 0 | W6: 0 | X6: 20000 | Y6: 0 | Z6: 0 | AA6: 0 | AB6: 0 | AC6: 20000 | AD6: 4.57045 | AE6: 91409 | AF6: USD | AG6: 84.03361 | AH6: 7681428.3
A7: 49560 | B7: EF102263 | C7: 1 | D7: CN43 | E7: CN43 | F7: FCI NANTONG LTD. | G7: FCI NANTONG LTD. | H7: IN56CX17 | I7: 45519 | J7: 10150562-001 | K7: 10150562-001 | L7: EA | M7: 10150562-001 HOUSING RPS04HBR01F | N7: 503 | O7: 22ZS | P7: 503BRKCA | Q7: 45576 | R7: 45576 | S7: 45576 | T7: 0 | U7: 0 | V7: 0 | W7: 0 | X7: 15000 | Y7: 0 | Z7: 0 | AA7: 0 | AB7: 0 | AC7: 15000 | AD7: 0.26688 | AE7: 4003.2 | AF7: USD | AG7: 84.03361 | AH7: 336403.35
A8: 49560 | B8: ET105556 | C8: 1 | D8: EACV02 | E8: EACV0206 | F8: VSELL ENTERPRISE CO. | G8: EACV02 | H8: 400004792 | I8: 45518 | J8: 10130664-9B0319HLF[AMPHENOL] | K8: 10130664-9B0319HLF | L8: EA | M8: 10130664-9B0319HLF BARKLIP CABLE ASSEMBLY | N8: 355 | O8: 22EF | P8: 503BRKCA | Q8: 45569 | R8: 45576 | S8: 45576 | T8: -7 | U8: 9840 | V8: 2180 | W8: 0 | X8: 25000 | Y8: 0 | Z8: 0 | AA8: 0 | AB8: 0 | AC8: 25000 | AD8: 22.92 | AE8: 573000 | AF8: USD | AG8: 84.03361 | AH8: 48151259 | AJ8: 45518
A9: 49560 | B9: EF102131 | C9: 6 | D9: US10 | E9: 31461 | F9: FCI USA LLC | G9: SANMINA SCI | H9: 410017 | I9: 45506 | J9: 10130664-9D0355LF | K9: 10130664-9D0355LF | L9: EA | M9: 10130664-9D0355LF BARKLIP CABLE ASSY-135MM | N9: 355 | O9: 22EF | P9: 503BRKCA | Q9: 45576 | R9: 45576 | S9: 45576 | T9: 0 | U9: 0 | V9: 0 | W9: 0 | X9: 720 | Y9: 0 | Z9: 0 | AA9: 0 | AB9: 0 | AC9: 720 | AD9: 5.6232 | AE9: 4048.7 | AF9: USD | AG9: 84.03361 | AH9: 340227.21
A10: 49560 | B10: ET105587 | C10: 1 | D10: EACV02 | E10: EACV0203 | F10: VSELL ENTERPRISE CO. | G10: EACV02 | H10: 400005117 | I10: 45538 | J10: 10162405-1S2009LF[AMPHENOL] | K10: 10162405-1S2009LF | L10: EA | M10: 10162405-1S2009LF BARKLIP CABLE ASSEMBLY | N10: 355 | O10: 20GF | P10: 503BRKCA | Q10: 45576 | R10: 45583 | S10: 45583 | T10: -7 | U10: 4400 | V10: 3308 | W10: 0 | X10: 2300 | Y10: 0 | Z10: 0 | AA10: 0 | AB10: 0 | AC10: 2300 | AD10: 10.43 | AE10: 23989 | AF10: USD | AG10: 84.03361 | AH10: 2015882.3 | AJ10: 45538
A11: 49560 | B11: EI33615 | C11: 10 | D11: EACA05 | E11: EACA0504 | F11: AVNET ASIA PTE Ltd | G11: Ingrasys Technology Mexi | H11: 6208763304 | I11: 45537 | J11: 35108WR00-245-G | K11: 10158287-9RF034HF | L11: EA | M11: 10158287-9RF034HF BK 300 CABLE ASSY | N11: 355 | O11: 22EF | P11: 503BRKCA | Q11: 45561 | R11: 45583 | S11: 45583 | T11: -22 | U11: 640 | V11: 700 | W11: 0 | X11: 10000 | Y11: 0 | Z11: 0 | AA11: 0 | AB11: 0 | AC11: 10000 | AD11: 14.11 | AE11: 141100 | AF11: USD | AG11: 84.03361 | AH11: 11857142
A12: 49560 | B12: EF102274 | C12: 3 | D12: US10 | E12: 314601 | F12: FCI USA LLC | G12: FCI Electronics | H12: 410896 | I12: 45521 | J12: 10130664-9D0354LF | K12: 10130664-9D0354LF | L12: EA | M12: 10130664-9D0354LF BARKLIP CABLE ASSY-196MM | N12: 355 | O12: 22EF | P12: 503BRKCA | Q12: 45583 | R12: 45583 | S12: 45583 | T12: 0 | U12: 312 | V12: 0 | W12: 0 | X12: 2160 | Y12: 0 | Z12: 0 | AA12: 0 | AB12: 0 | AC12: 2160 | AD12: 5.7816 | AE12: 12488 | AF12: USD | AG12: 84.03361 | AH12: 1049433.2
A13: 49560 | B13: EI32990 | C13: 10 | D13: EACA05 | E13: EACA0503 | F13: AVNET ASIA PTE Ltd | G13: EACA05 | H13: 6208716672 | I13: 45517 | J13: FCI10158287-9RF03> | K13: 10158287-9RF034HF | L13: EA | M13: 10158287-9RF034HF BK 300 CABLE ASSY | N13: 355 | O13: 22EF | P13: 503BRKCA | Q13: 45547 | R13: 45583 | S13: 45583 | T13: -36 | U13: 640 | V13: 700 | W13: 0 | X13: 10000 | Y13: 0 | Z13: 0 | AA13: 0 | AB13: 0 | AC13: 10000 | AD13: 14.11 | AE13: 141100 | AF13: USD | AG13: 84.03361 | AH13: 11857142
A14: 49560 | B14: ET105456 | C14: 1 | D14: EACA05 | E14: EACA0503 | F14: AVNET ASIA PTE Ltd | G14: EACA05 | H14: 6208662618 | I14: 45484 | J14: 10162405-1S2009LF | K14: 10162405-1S2009LF | L14: EA | M14: 10162405-1S2009LF BARKLIP CABLE ASSEMBLY | N14: 355 | O14: 20GF | P14: 503BRKCA | Q14: 45583 | R14: 45583 | S14: 45583 | T14: 0 | U14: 4400 | V14: 3308 | W14: 0 | X14: 10000 | Y14: 0 | Z14: 0 | AA14: 0 | AB14: 0 | AC14: 10000 | AD14: 10.86 | AE14: 108600 | AF14: USD | AG14: 84.03361 | AH14: 9049999.6 | AJ14: 45484
A15: 49560 | B15: EI34065 | C15: 10 | D15: EACA05 | E15: EACA0503 | F15: AVNET ASIA PTE Ltd | G15: EACA05 | H15: 6208794006 | I15: 45554 | J15: FCI10130664-1RF>B> | K15: 10130664-1RF474HF | L15: EA | M15: 10130664-1RF474HF BK200 IO CABLE ASSY | N15: 355 | O15: 22EF | P15: 355BRKCA | Q15: 45561 | R15: 45590 | S15: 45590 | T15: -29 | U15: 60 | V15: 0 | W15: 0 | X15: 1620 | Y15: 0 | Z15: 0 | AA15: 0 | AB15: 0 | AC15: 1620 | AD15: 30.37 | AE15: 49199 | AF15: USD | AG15: 84.03361 | AH15: 4134403.2
A16: 49560 | B16: EF102131 | C16: 7 | D16: US10 | E16: 31461 | F16: FCI USA LLC | G16: SANMINA SCI | H16: 410017 | I16: 45506 | J16: 10130664-9D0356LF | K16: 10130664-9D0356LF | L16: EA | M16: 10130664-9D0356LF BARKLIP CABLE ASSY-82MM | N16: 355 | O16: 22EF | P16: 503BRKCA | Q16: 45590 | R16: 45590 | S16: 45590 | T16: 0 | U16: 0 | V16: 96 | W16: 0 | X16: 720 | Y16: 0 | Z16: 0 | AA16: 0 | AB16: 0 | AC16: 720 | AD16: 5.4 | AE16: 3888 | AF16: USD | AG16: 84.03361 | AH16: 326722.68
A17: 49560 | B17: ET105497 | C17: 1 | D17: EUCF02 | E17: EUCF0201 | F17: FLEXTRONICS INTERNATIONA | G17: EUCF02 | H17: 269P18095 | I17: 45502 | J17: AMZ-216-003899-001 | K17: 10130664-1RF474HF | L17: EA | M17: 10130664-1RF474HF BK200 IO CABLE ASSY | N17: 355 | O17: 22EF | P17: 355BRKCA | Q17: 45590 | R17: 45590 | S17: 45590 | T17: 0 | U17: 60 | V17: 0 | W17: 0 | X17: 1000 | Y17: 0 | Z17: 0 | AA17: 0 | AB17: 0 | AC17: 1000 | AD17: 34.93 | AE17: 34930 | AF17: USD | AG17: 84.03361 | AH17: 2910833.2 | AJ17: 45502
A18: 49560 | B18: EI32675 | C18: 10 | D18: EACA05 | E18: EACA0503 | F18: AVNET ASIA PTE Ltd | G18: EACA05 | H18: 6208691032 | I18: 45499 | J18: FCI10162405-1S2>>> | K18: 10162405-1S2009LF | L18: EA | M18: 10162405-1S2009LF BARKLIP CABLE ASSEMBLY | N18: 355 | O18: 20GF | P18: 503BRKCA | Q18: 45590 | R18: 45590 | S18: 45590 | T18: 0 | U18: 4400 | V18: 3308 | W18: 0 | X18: 15000 | Y18: 0 | Z18: 0 | AA18: 0 | AB18: 0 | AC18: 15000 | AD18: 10.86 | AE18: 162900 | AF18: USD | AG18: 84.03361 | AH18: 13574999
A19: 49560 | B19: ET105478 | C19: 10 | D19: EUCF02 | E19: EUCF0201 | F19: FLEXTRONICS INTERNATIONA | G19: EUCF02 | H19: 269P18066 | I19: 45495 | J19: AMZ-216-003899-001 | K19: 10130664-1RF474HF | L19: EA | M19: 10130664-1RF474HF BK200 IO CABLE ASSY | N19: 355 | O19: 22EF | P19: 355BRKCA | Q19: 45590 | R19: 45590 | S19: 45590 | T19: 0 | U19: 60 | V19: 0 | W19: 0 | X19: 1000 | Y19: 0 | Z19: 0 | AA19: 0 | AB19: 0 | AC19: 1000 | AD19: 34.93 | AE19: 34930 | AF19: USD | AG19: 84.03361 | AH19: 2910833.2 | AJ19: 45495
A20: 49560 | B20: EF100293 | C20: 4 | D20: TW00 | E20: 460010 | F20: FCI TAIWAN | G20: QUADREP ELECTRONICS LTD | H20: N6Q41167 | I20: 45308 | J20: 10158287-9RF034HF | K20: 10158287-9RF034HF | L20: EA | M20: 10158287-9RF034HF BK 300 CABLE ASSY | N20: 355 | O20: 22EF | P20: 503BRKCA | Q20: 45590 | R20: 45590 | S20: 45590 | T20: 0 | U20: 640 | V20: 700 | W20: 0 | X20: 15000 | Y20: 0 | Z20: 0 | AA20: 0 | AB20: 0 | AC20: 15000 | AD20: 14.84547 | AE20: 222682 | AF20: USD | AG20: 84.03361 | AH20: 18556837
A21: 49560 | B21: DISP0067 | C21: 1 | D21: IBCA51 | E21: IBCA5102 | F21: Avnet India Pvt. Ltd | G21: AVNET INDIA PVT LTD | H21: 6208790310 | I21: 45558 | K21: 10130664-9SF463LF | L21: EA | M21: 10130664-9SF463LF BK200 I/O Cable Assembly | N21: 355 | O21: 22EF | P21: 355BRKCA | Q21: 45569 | R21: 54700 | S21: 54700 | T21: -9131 | U21: 0 | V21: 0 | W21: 0 | X21: 100 | Y21: 0 | Z21: 0 | AA21: 0 | AB21: 0 | AC21: 100 | AD21: 4627.26 | AE21: 462726 | AF21: INR | AG21: 1 | AH21: 462726 | AJ21: 45558
A22: 49560 | B22: DISP0066 | C22: 1 | D22: IBCA51 | E22: IBCA5102 | F22: Avnet India Pvt. Ltd | G22: AVNET INDIA PVT LTD | H22: 6208790311 | I22: 45558 | K22: 10130664-9SF463LF | L22: EA | M22: 10130664-9SF463LF BK200 I/O Cable Assembly | N22: 355 | O22: 22EF | P22: 355BRKCA | Q22: 45569 | R22: 54700 | S22: 54700 | T22: -9131 | U22: 0 | V22: 0 | W22: 0 | X22: 400 | Y22: 0 | Z22: 0 | AA22: 0 | AB22: 0 | AC22: 400 | AD22: 4627.26 | AE22: 1850904 | AF22: INR | AG22: 1 | AH22: 1850904 | AJ22: 45558
A23: 49560 | B23: ET105546 | C23: 1 | D23: EACV03 | E23: EACV0301 | F23: VSELL ENTERPRISE CO. | G23: EACV03 | H23: 400004677 | I23: 45509 | J23: B50.0260X.0021 | K23: 10130664-9B0319HLF | L23: EA | M23: 10130664-9B0319HLF BARKLIP CABLE ASSEMBLY | N23: 355 | O23: 22EF | P23: 503BRKCA | Q23: 45597 | R23: 45597 | S23: 45597 | T23: 0 | U23: 10080 | V23: 1940 | W23: 0 | X23: 2200 | Y23: 0 | Z23: 0 | AA23: 0 | AB23: 0 | AC23: 2200 | AD23: 22.92 | AE23: 50424 | AF23: USD | AG23: 84.03361 | AH23: 4237310.8 | AJ23: 45509
A24: 49560 | B24: EF102491 | C24: 2 | D24: CN43 | E24: CN43 | F24: FCI NANTONG LTD. | G24: FCI NANTONG LTD. | H24: IN24CT01 | I24: 45542 | J24: 10150562-001 | K24: 10150562-001 | L24: EA | M24: 10150562-001 HOUSING RPS04HBR01F | N24: 503 | O24: 22ZS | P24: 503BRKCA | Q24: 45604 | R24: 45604 | S24: 45604 | T24: 0 | U24: 0 | V24: 0 | W24: 0 | X24: 10000 | Y24: 0 | Z24: 0 | AA24: 0 | AB24: 0 | AC24: 10000 | AD24: 0.26688 | AE24: 2668.8 | AF24: USD | AG24: 84.03361 | AH24: 224268.9
A25: 49560 | B25: EF102491 | C25: 1 | D25: CN43 | E25: CN43 | F25: FCI NANTONG LTD. | G25: FCI NANTONG LTD. | H25: IN24CT01 | I25: 45542 | J25: 10150562-001 | K25: 10150562-001 | L25: EA | M25: 10150562-001 HOUSING RPS04HBR01F | N25: 503 | O25: 22ZS | P25: 503BRKCA | Q25: 45597 | R25: 45604 | S25: 45604 | T25: -7 | U25: 0 | V25: 0 | W25: 0 | X25: 10000 | Y25: 0 | Z25: 0 | AA25: 0 | AB25: 0 | AC25: 10000 | AD25: 0.26688 | AE25: 2668.8 | AF25: USD | AG25: 84.03361 | AH25: 224268.9
A26: 49560 | B26: EF102274 | C26: 4 | D26: US10 | E26: 314601 | F26: FCI USA LLC | G26: FCI Electronics | H26: 410896 | I26: 45521 | J26: 10130664-9D0355LF | K26: 10130664-9D0355LF | L26: EA | M26: 10130664-9D0355LF BARKLIP CABLE ASSY-135MM | N26: 355 | O26: 22EF | P26: 503BRKCA | Q26: 45604 | R26: 45604 | S26: 45604 | T26: 0 | U26: 0 | V26: 0 | W26: 0 | X26: 2880 | Y26: 0 | Z26: 0 | AA26: 0 | AB26: 0 | AC26: 2880 | AD26: 5.6232 | AE26: 16195 | AF26: USD | AG26: 84.03361 | AH26: 1360908.9
A27: 49560 | B27: EF102274 | C27: 5 | D27: US10 | E27: 314601 | F27: FCI USA LLC | G27: FCI Electronics | H27: 410896 | I27: 45521 | J27: 10130664-9D0356LF | K27: 10130664-9D0356LF | L27: EA | M27: 10130664-9D0356LF BARKLIP CABLE ASSY-82MM | N27: 355 | O27: 22EF | P27: 503BRKCA | Q27: 45604 | R27: 45604 | S27: 45604 | T27: 0 | U27: 0 | V27: 96 | W27: 0 | X27: 2160 | Y27: 0 | Z27: 0 | AA27: 0 | AB27: 0 | AC27: 2160 | AD27: 5.4 | AE27: 11664 | AF27: USD | AG27: 84.03361 | AH27: 980168.03
AH28: =SUM(AH2:AH27) -> 1.6740339e+08
AH29: =AH28/(84.03361*1000) -> 1992.1004

Sheet PN-workout file
A1: Lines | B1: Item Number | C1: Description | D1: Qty. | E1: CT | I1: Hrs. | N1: HC/ Day | O1: Sunday working-HC | P1: LR @12% | R1: Remarks
E2: MA | F2: MA | G2: I&P | H2: Total | I2: MA | J2: I&P | K2: Total | M2: Target/day | Q2: Total HC | S2: Wire cutting | T2: Cropping | U2: Welding | V2: Sum
A3: BK Cable | B3: 10130664-9RF438LF | C3: Meta/Amazon | D3: 79720 | E3: =0.15-(V3) -> 0.12083333 | F3: 0.21 | G3: 0.03125 | H3: =E3+G3 -> 0.15208333 | I3: =F3*D3 -> 16741.2 | J3: =G3*D3 -> 2491.25 | K3: =SUM(I3:J3) -> 19232.45 | M3: =D3/$X$5 -> 2952.5926 | N3: =D3*H3/$X$5/7.05/$X$4 -> 70.770705 | P3: =N3*0.12 -> 8.4924846 | Q3: =N3+O3+P3 -> 79.26319 | S3: =20/3600 -> 0.0055555556 | T3: =20/3600 -> 0.0055555556 | U3: =65/3600 -> 0.018055556 | V3: =SUM(S3:U3) -> 0.029166667
B4: 10158287-1RF057HF | C4: BK300 | D4: 34000 | E4: =(0.225)-(V4) -> 0.16361111 | F4: =0.225 -> 0.225 | G4: =0.0413888*0.8 -> 0.03311104 | H4: =E4+G4 -> 0.19672215 | I4: =F4*D4 -> 7650 | J4: =G4*D4 -> 1125.7754 | K4: =SUM(I4:J4) -> 8775.7754 | M4: =D4/$X$5 -> 1259.2593 | N4: =D4*H4/$X$5/7.05/$X$4 -> 39.042426 | P4: =N4*0.12 -> 4.6850911 | Q4: =N4+O4+P4 -> 43.727517 | S4: =31/3600 -> 0.0086111111 | T4: =10/3600 -> 0.0027777778 | U4: =180/3600 -> 0.05 | V4: =SUM(S4:U4) -> 0.061388889 | W4: DL % | X4: 0.9
B5: 10162405-1S2009LF | C5: BK50 | D5: 38000 | E5: 0.099 | F5: =0.1 -> 0.1 | G5: 0.00807 | H5: =E5+G5 -> 0.10707 | I5: =F5*D5 -> 3800 | J5: =G5*D5 -> 306.66 | K5: =SUM(I5:J5) -> 4106.66 | M5: =D5/$X$5 -> 1407.4074 | N5: =D5*H5/$X$5/7.05/$X$4 -> 23.749584 | P5: =(N5*0.12) -> 2.8499501 | Q5: =N5+O5+P5 -> 26.599534 | W5: Working days | X5: 27
B6: 10130664-9D0354LF | C6: TESLA | D6: 9840 | E6: =0.17-V6 -> 0.15194444 | F6: 0.17 | G6: 0.03 | H6: =E6+G6 -> 0.18194444 | I6: =F6*D6 -> 1672.8 | J6: =G6*D6 -> 295.2 | K6: =SUM(I6:J6) -> 1968 | M6: =D6/$X$5 -> 364.44444 | N6: =D6*H6/$X$5/7.05/$X$4 -> 10.450535 | P6: =N6*0.12 -> 1.2540642 | Q6: =N6+O6+P6 -> 11.704599 | S6: =15/3600 -> 0.0041666667 | T6: =10/3600 -> 0.0027777778 | U6: =40/3600 -> 0.011111111 | V6: =SUM(S6:U6) -> 0.018055556
B7: 10170425-9SF025LF | C7: TETON2 | D7: 150000 | E7: =(1300/3600)-V7 -> 0.25277778 | F7: =1200/3600 -> 0.33333333 | G7: =150/3600 -> 0.041666667 | H7: =E7+G7 -> 0.29444444 | I7: =F7*D7 -> 50000 | J7: =G7*D7 -> 6250 | K7: =SUM(I7:J7) -> 56250 | M7: =D7/$X$5 -> 5555.5556 | N7: =D7*H7/$X$5/7.05/$X$4 -> 257.80969 | O7: =N7/6 -> 42.968281 | P7: =N7*0.12 -> 30.937163 | Q7: =N7+O7+P7 -> 331.71513 | S7: =70/3600 -> 0.019444444 | T7: =70/3600 -> 0.019444444 | U7: =250/3600 -> 0.069444444 | V7: =SUM(S7:U7) -> 0.10833333
A8: Connector | B8: 10165987-101LF | C8: ASM | D8: 500000 | E8: 0.0079861 | G8: 0.0053833 | H8: =SUM(E8:G8) -> 0.0133694 | I8: =E8*D8 -> 3993.05 | J8: =G8*D8 -> 2691.65 | K8: =SUM(I8:J8) -> 6684.7 | M8: =D8/$X$5 -> 18518.519 | N8: =D8*H8/$X$5/7.05/$X$4 -> 39.019934 | P8: =N8*0.12 -> 4.6823921 | Q8: =N8+O8+P8 -> 43.702326 | S8: =16*4 -> 64
B9: 10168675-001LF | C9: Lockpin | D9: 462000 | E9: 0.000905 | G9: 0.0053833 | H9: =SUM(E9:G9) -> 0.0062883 | I9: =E9*D9 -> 418.11 | J9: =G9*D9 -> 2487.0846 | K9: =SUM(I9:J9) -> 2905.1946 | M9: =D9/$X$5 -> 17111.111 | N9: =D9*H9/$X$5/7.05/$X$4 -> 16.958203 | P9: =ROUNDUP(N9*0.12,0) -> 3 | Q9: =N9+O9+P9 -> 19.958203
B10: 10174922-001LF | C10: Z2/Z4 | E10: 0.0079861 | G10: 0.0053833 | H10: =SUM(E10:G10) -> 0.0133694 | I10: =E10*D10 -> 0 | J10: =G10*D10 -> 0 | K10: =SUM(I10:J10) -> 0 | M10: =D10/$X$5 -> 0 | N10: =D10*H10/$X$5/7.05/$X$4 -> 0 | P10: =ROUNDUP(N10*0.12,0) -> 0 | Q10: =N10+O10+P10 -> 0
B11: 10157266-001LF | C11: BK200 XP | D11: 25000 | E11: 0.01818 | G11: 0.00964 | H11: =SUM(E11:G11) -> 0.02782 | I11: =E11*D11 -> 454.5 | J11: =G11*D11 -> 241 | K11: =SUM(I11:J11) -> 695.5 | M11: =D11/$X$5 -> 925.92593 | N11: =D11*H11/$X$5/7.05/$X$4 -> 4.0597729 | P11: =N11*0.12 -> 0.48717275 | Q11: =N11+O11+P11 -> 4.5469457
B12: HPG36P14SRT051TH07 | C12: EEX | D12: 1500 | E12: =150/3600 -> 0.041666667 | G12: 0.013 | H12: =E12+G12 -> 0.054666667 | I12: =E12*D12 -> 62.5 | J12: =G12*D12 -> 19.5 | K12: =SUM(I12:J12) -> 82 | M12: =D12/$X$5 -> 55.555556 | N12: =D12*H12/$X$5/7.05/$X$4 -> 0.47865044 | P12: =N12*0.12 -> 0.057438053 | Q12: =N12+O12+P12 -> 0.53608849
B13: 10173947-100012LF | C13: 48V Connector | D13: 102328 | E13: =23/3600 -> 0.0063888889 | G13: 0.0048 | H13: =E13+G13 -> 0.011188889 | I13: =E13*D13 -> 653.76222 | J13: =G13*D13 -> 491.1744 | K13: =SUM(I13:J13) -> 1144.9366 | M13: =D13/$X$5 -> 3789.9259 | N13: =D13*H13/$X$5/7.05/$X$4 -> 6.6832246 | P13: =N13*0.12 -> 0.80198695 | Q13: =N13+O13+P13 -> 7.4852116
B14: 10170827-07P003 | C14: ORV3-Connector | D14: 62154 | E14: =150/3600 -> 0.041666667 | G14: 0.032 | H14: =E14+G14 -> 0.073666667 | I14: =E14*D14 -> 2589.75 | J14: =G14*D14 -> 1988.928 | K14: =SUM(I14:J14) -> 4578.678 | M14: =D14/$X$5 -> 2302 | N14: =D14*H14/$X$5/7.05/$X$4 -> 26.726661 | P14: =N14*0.12 -> 3.2071994 | Q14: =N14+O14+P14 -> 29.933861
E15: 0.033 | G15: 0.008 | H15: =E15+G15 -> 0.041 | I15: =E15*D15 -> 0 | J15: =G15*D15 -> 0 | K15: =SUM(I15:J15) -> 0 | M15: =D15/$X$5 -> 0 | N15: =D15*H15/$X$5/7.05/$X$4 -> 0 | P15: =N15*0.12 -> 0 | Q15: =N15+O15+P15 -> 0
B16: 10170820-001LF | C16: IPC Battery | D16: 2000 | E16: 0.004 | G16: 0.0025 | H16: =E16+G16 -> 0.0065 | I16: =E16*D16 -> 8 | J16: =G16*D16 -> 5 | K16: =SUM(I16:J16) -> 13 | M16: =D16/$X$5 -> 74.074074 | N16: =D16*H16/$X$5/7.05/$X$4 -> 0.075883606 | P16: =N16*0.12 -> 0.0091060327 | Q16: =N16+O16+P16 -> 0.084989639
B17: C10176572-B000R | C17: CSD | D17: 40000 | E17: =0.05225 -> 0.05225 | G17: =80/3600 -> 0.022222222 | H17: =E17+G17 -> 0.074472222 | I17: =E17*D17 -> 2090 | J17: =G17*D17 -> 888.88889 | K17: =SUM(I17:J17) -> 2978.8889 | M17: =D17/$X$5 -> 1481.4815 | N17: =D17*H17/$X$5/7.05/$X$4 -> 17.388372 | P17: =N17*0.12 -> 2.0866046 | Q17: =N17+O17+P17 -> 19.474976
B18: 10174780-001LF | C18: ET30 | D18: =18000+29110 -> 47110 | E18: 0.016 | G18: 0.005 | H18: =E18+G18 -> 0.021 | I18: =E18*D18 -> 753.76 | J18: =G18*D18 -> 235.55 | K18: =SUM(I18:J18) -> 989.31 | M18: =D18/$X$5 -> 1744.8148 | N18: =D18*H18/$X$5/7.05/$X$4 -> 5.7748008 | P18: =N18*0.12 -> 0.6929761 | Q18: =N18+O18+P18 -> 6.4677769
C19: FIT30 | E19: 0.0472222 | G19: 0.0107639 | H19: =E19+G19 -> 0.0579861 | I19: =E19*D19 -> 0 | J19: =G19*D19 -> 0 | K19: =SUM(I19:J19) -> 0 | M19: =D19/$X$5 -> 0 | N19: =D19*H19/$X$5/7.05/$X$4 -> 0 | P19: =N19*0.12 -> 0 | Q19: =N19+O19+P19 -> 0
B20: PWRMRA028 | C20: ET20 | D20: 66400 | E20: =70/3600 -> 0.019444444 | G20: 0.0079861 | H20: =E20+G20 -> 0.027430544 | I20: =E20*D20 -> 1291.1111 | J20: =G20*D20 -> 530.27704 | K20: =SUM(I20:J20) -> 1821.3882 | M20: =D20/$X$5 -> 2459.2593 | N20: =D20*H20/$X$5/7.05/$X$4 -> 10.631808 | P20: =N20*0.12 -> 1.2758169 | Q20: =N20+O20+P20 -> 11.907625
C21: BK350 | D21: 136584 | E21: 0.0100694 | G21: 0.0041667 | H21: =E21+G21 -> 0.0142361 | I21: =E21*D21 -> 1375.3189 | J21: =G21*D21 -> 569.10455 | K21: =SUM(I21:J21) -> 1944.4235 | M21: =D21/$X$5 -> 5058.6667 | N21: =D21*H21/$X$5/7.05/$X$4 -> 11.34999 | P21: =N21*0.12 -> 1.3619988 | Q21: =N21+O21+P21 -> 12.711988
B22: 10170775-170502 | C22: ORV3 CONNECTOR | D22: 15008 | E22: =200/3600 -> 0.055555556 | G22: 0.009 | H22: =E22+G22 -> 0.064555556 | I22: =E22*D22 -> 833.77778 | J22: =G22*D22 -> 135.072 | K22: =SUM(I22:J22) -> 968.84978 | M22: =D22/$X$5 -> 555.85185 | N22: =D22*H22/$X$5/7.05/$X$4 -> 5.6553704 | P22: =N22*0.12 -> 0.67864445 | Q22: =N22+O22+P22 -> 6.3340148
B23: 10182948-Q50001 | C23: ACWHIP Qseries | E23: 0.56 | G23: 0.14 | H23: =E23+G23 -> 0.7 | I23: =E23*D23 -> 0 | J23: =G23*D23 -> 0 | K23: =SUM(I23:J23) -> 0 | M23: =D23/$X$5 -> 0 | N23: =D23*H23/$X$5/7.05/$X$4 -> 0 | P23: =N23*0.12 -> 0 | Q23: =N23+O23+P23 -> 0
B24: 10178161-C7A303 (30 Amps) | C24: ORV3 | E24: =1400/3600 -> 0.38888889 | F24: 0.58 | G24: 0.145 | H24: =E24+G24 -> 0.53388889 | I24: =E24*D24 -> 0 | J24: =G24*D24 -> 0 | K24: =SUM(I24:J24) -> 0 | M24: =D24/$X$5 -> 0 | N24: =D24*H24/$X$5/7.05/$X$4 -> 0 | O24: =N24*(1/6) -> 0 | P24: =(N24+O24)*0.12 -> 0 | Q24: =N24+O24+P24 -> 0
B25: 10176859-001LF | C25: Energypole | D25: 31000 | E25: =84/3600 -> 0.023333333 | G25: 0.03 | H25: =E25+G25 -> 0.053333333 | I25: =E25*D25 -> 723.33333 | J25: =G25*D25 -> 930 | K25: =SUM(I25:J25) -> 1653.3333 | M25: =D25/$X$5 -> 1148.1481 | N25: =D25*H25/$X$5/7.05/$X$4 -> 9.6508381 | P25: =N25*0.12 -> 1.1581006 | Q25: =N25+O25+P25 -> 10.808939
A26: ACWHIP | B26: RPS07007X9-004 (20 Amps) | C26: ORV3 | D26: 15425 | E26: =1000/3600 -> 0.27777778 | G26: =300/3600 -> 0.083333333 | H26: =E26+G26 -> 0.36111111 | I26: =E26*D26 -> 4284.7222 | J26: =G26*D26 -> 1285.4167 | K26: =SUM(I26:J26) -> 5570.1389 | M26: =D26/$X$5 -> 571.2963 | N26: =D26*H26/$X$5/7.05/$X$4 -> 32.514017 | P26: =N26*0.12 -> 3.9016821 | Q26: =N26+O26+P26 -> 36.415699
B27: 10180876-E7C01 | C27: ORV3 | D27: 25092 | E27: =1200/3600 -> 0.33333333 | F27: 0.65 | G27: 0.1453 | H27: =E27+G27 -> 0.47863333 | I27: =E27*D27 -> 8364 | J27: =G27*D27 -> 3645.8676 | K27: =SUM(I27:J27) -> 12009.868 | M27: =D27/$X$5 -> 929.33333 | N27: =D27*H27/$X$5/7.05/$X$4 -> 70.104005 | P27: =N27*0.12 -> 8.4124806 | Q27: =N27+O27+P27 -> 78.516485
B28: 10188304-054F01 | C28: ORV3-100A | D28: 1000 | E28: 0.38 | F28: 0.46 | G28: =500/3600 -> 0.13888889 | H28: =E28+G28 -> 0.51888889 | I28: =E28*D28 -> 380 | J28: =G28*D28 -> 138.88889 | K28: =SUM(I28:J28) -> 518.88889 | M28: =D28/$X$5 -> 37.037037 | N28: =D28*H28/$X$5/7.05/$X$4 -> 3.0288585 | P28: =N28*0.12 -> 0.36346302 | Q28: =N28+O28+P28 -> 3.3923215
B29: 10182665-3RF001LF | C29: ORV3 | E29: 0.065 | G29: 0.009 | H29: =E29+G29 -> 0.074 | I29: =E29*D29 -> 0 | J29: =G29*D29 -> 0 | K29: =SUM(I29:J29) -> 0 | M29: =D29/$X$5 -> 0 | N29: =D29*H29/$X$5/7.05/$X$4 -> 0 | P29: =N29*0.12 -> 0 | Q29: =N29+O29+P29 -> 0
B30: 1018106X-K7000X (K series) | C30: ORV3 | D30: 60000 | E30: =1000/3600 -> 0.27777778 | F30: 0.61 | G30: =280/3600 -> 0.077777778 | H30: =E30+G30 -> 0.35555556 | I30: =E30*D30 -> 16666.667 | J30: =G30*D30 -> 4666.6667 | K30: =SUM(I30:J30) -> 21333.333 | M30: =D30/$X$5 -> 2222.2222 | N30: =D30*H30/$X$5/7.05/$X$4 -> 124.52694 | P30: =(N30+O30)*0.12 -> 14.943233 | Q30: =N30+O30+P30 -> 139.47018
B31: 10176873-19-F140LF | C31: ORV3-60A | D31: 8510 | E31: =3000/3600 -> 0.83333333 | F31: 0.8 | G31: =500/3600 -> 0.13888889 | H31: =E31+G31 -> 0.97222222 | I31: =E31*D31 -> 7091.6667 | J31: =G31*D31 -> 1181.9444 | K31: =SUM(I31:J31) -> 8273.6111 | M31: =D31/$X$5 -> 315.18519 | N31: =D31*H31/$X$5/7.05/$X$4 -> 48.294727 | P31: =N31*0.12 -> 5.7953672 | Q31: =N31+O31+P31 -> 54.090094
B32: 10187162-002LF | C32: ORV3-60A- IC | D32: 14140 | E32: 0.123 | F32: 0.123 | G32: 0.319 | H32: =E32+G32 -> 0.442 | I32: =E32*D32 -> 1739.22 | J32: =G32*D32 -> 4510.66 | K32: =SUM(I32:J32) -> 6249.88 | M32: =D32/$X$5 -> 523.7037 | N32: =D32*H32/$X$5/7.05/$X$4 -> 36.481803 | P32: =N32*0.12 -> 4.3778163 | Q32: =N32+O32+P32 -> 40.859619
B33: 10176873-37-F247LF | C33: ORV3-60A | E33: 0.7 | G33: 0.32 | H33: =E33+G33 -> 1.02 | I33: =E33*D33 -> 0 | J33: =G33*D33 -> 0 | K33: =SUM(I33:J33) -> 0 | M33: =D33/$X$5 -> 0 | N33: =D33*H33/$X$5/7.05/$X$4 -> 0 | P33: =N33*0.12 -> 0 | Q33: =N33+O33+P33 -> 0
B34: 10176873-18-F126LF | C34: ORV3-60A | E34: 0.61 | G34: 0.31 | H34: =E34+G34 -> 0.92 | I34: =E34*D34 -> 0 | J34: =G34*D34 -> 0 | K34: =SUM(I34:J34) -> 0 | M34: =D34/$X$5 -> 0 | N34: =D34*H34/$X$5/7.05/$X$4 -> 0 | P34: =N34*0.12 -> 0 | Q34: =N34+O34+P34 -> 0
A35: BK Cable | B35: 10146534-1EP063LF | C35: BK 100 Cable | D35: 20814 | E35: =0.065-V35 -> 0.046944444 | F35: 0.065 | G35: 0.022 | H35: =E35+G35 -> 0.068944444 | I35: =F35*D35 -> 1352.91 | J35: =G35*D35 -> 457.908 | K35: =SUM(I35:J35) -> 1810.818 | M35: =D35/$X$5 -> 770.88889 | N35: =D35*H35/$X$5/7.05/$X$4 -> 8.3764391 | P35: =N35*0.12 -> 1.0051727 | Q35: =N35+O35+P35 -> 9.3816118 | S35: =15/3600 -> 0.0041666667 | T35: =10/3600 -> 0.0027777778 | U35: =2*20/3600 -> 0.011111111 | V35: =SUM(S35:U35) -> 0.018055556
B36: 10174690-1UF026LF | C36: Oracle | E36: 0.295472 | G36: 0.0277778 | H36: =E36+G36 -> 0.3232498 | I36: =E36*D36 -> 0 | J36: =G36*D36 -> 0 | K36: =SUM(I36:J36) -> 0 | M36: =D36/$X$5 -> 0 | N36: =D36*H36/$X$5/7.05/$X$4 -> 0 | P36: =N36*0.12 -> 0 | Q36: =N36+O36+P36 -> 0
B37: 10170425-9B0040LF | C37: BK350 | D37: 23600 | E37: 0.145 | G37: 0.008 | H37: =E37+G37 -> 0.153 | I37: =E37*D37 -> 3422 | J37: =G37*D37 -> 188.8 | K37: =SUM(I37:J37) -> 3610.8 | M37: =D37/$X$5 -> 874.07407 | N37: =D37*H37/$X$5/7.05/$X$4 -> 21.076963 | P37: =N37*0.12 -> 2.5292356 | Q37: =N37+O37+P37 -> 23.606199
B38: 10174690-1UF011LF | C38: BK220 I/O Cable Assembly | E38: =0.24-V38 -> 0.19333333 | F38: 0.24 | G38: 0.02 | H38: =E38+G38 -> 0.21333333 | I38: =F38*D38 -> 0 | J38: =G38*D38 -> 0 | K38: =SUM(I38:J38) -> 0 | M38: =D38/$X$5 -> 0 | N38: =D38*H38/$X$5/7.05/$X$4 -> 0 | P38: =N38*0.12 -> 0 | Q38: =N38+O38+P38 -> 0 | S38: =36/3600 -> 0.01 | U38: =22*6/3600 -> 0.036666667 | V38: =SUM(S38:U38) -> 0.046666667
B39: 10146534-9B0001LF | C39: BK ZOID | D39: 67000 | E39: =0.302-0.017 -> 0.285 | F39: 0.322 | G39: 0.04 | H39: =E39+G39 -> 0.325 | I39: =F39*D39 -> 21574 | J39: =G39*D39 -> 2680 | K39: =SUM(I39:J39) -> 24254 | M39: =D39/$X$5 -> 2481.4815 | N39: =D39*H39/$X$5/7.05/$X$4 -> 127.10504 | P39: =N39*0.12 -> 15.252605 | Q39: =N39+O39+P39 -> 142.35765
B40: 10170744-9D0001LF | C40: BK250 | D40: 21000 | E40: =0.26-V40 -> 0.20555556 | F40: 0.28 | G40: 0.03 | H40: =E40+G40 -> 0.23555556 | I40: =F40*D40 -> 5880 | J40: =G40*D40 -> 630 | K40: =SUM(I40:J40) -> 6510 | M40: =D40/$X$5 -> 777.77778 | N40: =D40*H40/$X$5/7.05/$X$4 -> 28.874685 | P40: =N40*0.12 -> 3.4649622 | Q40: =N40+O40+P40 -> 32.339647 | S40: =36/3600 -> 0.01 | U40: =20*8/3600 -> 0.044444444 | V40: =SUM(S40:U40) -> 0.054444444
...

Sheet Sheet7

Sheet Machine crew-Cable
D3: Sunday working
D5: Operator | E5: 35 | F5: =E5*3 -> 105
D6: Twisting | E6: 3 | F6: 18
D7: cable cutting | F7: 6 | I7: Teton | J7: 18
D8: Cropping | F8: 8 | I8: BK300 | J8: 3
D9: Support | F9: =J11 -> 35 | I9: Meta | J9: 2
I10: 48v/ Nvdia | J10: 12
J11: =SUM(J5:J10) -> 35
F13: =SUM(F5:F12) -> 172
F14: Sunday | G14: =(F13)/6 -> 28.666667
F15: total | G15: =ROUNDUP(G14+F13,0) -> 201
F16: LR | G16: =ROUNDUP(G15*0.12,0) -> 25
F17: total incl LR | G17: =G16+G15 -> 226

Sheet Supporting HC details
F5: Supporting DL
G6: BK Cable | H6: BK Revised | I6: AC Cable | J6: Connector
F7: Lead | G7: 15 | H7: 20 | I7: 12 | J7: 8 | M7: =2100/55 -> 38.181818
F8: Store work | G8: 6 | H8: 10 | J8: 3
F9: Technician | G9: 4 | H9: 4 | I9: 6 | J9: 12
F10: Scrap work and data entry | G10: 7 | H10: 7 | I10: 7 | J10: 3
F12: Supp: Total | G12: =SUM(G7:G11) -> 32 | H12: =SUM(H7:H11) -> 41 | I12: =SUM(I7:I11) -> 25 | J12: =SUM(J7:J11) -> 26 | K12: =SUM(H12:J12) -> 92
F14: Total | G14: =K12 -> 92

Sheet Capacity
A1: Current capacity
A2: BK300 | B2: Weld type | C2: Qty/FG | E2: CT | G2: Total CT | H2: No: of M/c | I2: O/t-Shift | J2: O/t-Day | K2: FG/Day | L2: Monthly capacity
B3: Metal welding | C3: 4 | E3: 15 | G3: =E3*C3 -> 60 | H3: 2 | I3: =8/(G3/3600)*H3 -> 960 | J3: =I3*3*0.8 -> 2304 | K3: =MIN(J3:J5) -> 1645.7143 | L3: =K3*25 -> 41142.857
B4: Wire welding | C4: 4 | E4: 15 | G4: =E4*C4 -> 60 | H4: 2 | I4: =8/(G4/3600)*H4 -> 960 | J4: =I4*3*0.8 -> 2304
B5: Z welding | C5: 4 | E5: 21 | G5: =E5*C5 -> 84 | H5: 2 | I5: =8/(G5/3600)*H5 -> 685.71429 | J5: =I5*3*0.8 -> 1645.7143
A6: Teton | B6: Wire welding | C6: 4 | E6: 20 | G6: =C6*E6 -> 80 | I6: =8/(G6/3600)*H6 -> 0 | J6: =I6*3*0.8 -> 0 | K6: =MIN(J6:J7) -> 0 | L6: =K6*26 -> 0
B7: Metal welding | C7: 4 | E7: 15 | G7: =C7*E7 -> 60 | I7: =8/(G7/3600)*H7 -> 0 | J7: =I7*3*0.8 -> 0
A8: Meta-Facebook | B8: Metal welding | C8: 2 | E8: 13 | G8: =E8*C8 -> 26 | H8: 1 | I8: =8/(G8/3600)*H8 -> 1107.6923 | J8: =I8*3*0.8 -> 2658.4615 | K8: =MIN(J8:J9) -> 2658.4615 | L8: =K8*26 -> 69120
B9: 5 Wire welding | C9: 2 | E9: 25 | G9: =E9*C9 -> 50 | H9: 2 | I9: =8/(G9/3600)*H9 -> 1152 | J9: =I9*3*0.8 -> 2764.8
A10: Tesla | B10: Wire welding | C10: 1 | E10: 40 | G10: =E10*C10 -> 40 | H10: 2 | I10: =8/(G10/3600)*H10 -> 1440 | J10: =I10*3*0.8 -> 3456 | K10: =J10 -> 3456 | L10: =K10*26 -> 89856
A12: Total | H12: =SUM(H3:H11) -> 11 | L12: =SUM(L3:L11) -> 200118.86
A15: Capacity by Q4-2024
A16: BK300 | B16: Weld type | C16: Qty/FG | E16: CT | G16: Total CT | H16: No: of M/c | I16: O/t-Shift | J16: O/t-Day | K16: FG/Day | L16: Monthly capacity
B17: Metal welding | C17: 4 | E17: 15 | G17: =E17*C17 -> 60 | H17: 2 | I17: =8/(G17/3600)*H17 -> 960 | J17: =I17*3*0.8 -> 2304 | K17: =MIN(J17:J19) -> 1920 | L17: =K17*26 -> 49920 | N17: =L26-L12 -> -4156.6753
B18: Wire welding | C18: 4 | E18: 15 | G18: =E18*C18 -> 60 | H18: 2 | I18: =8/(G18/3600)*H18 -> 960 | J18: =I18*3*0.8 -> 2304 | N18: =N17/L12 -> -0.020771033
B19: Z welding | C19: 4 | E19: 18 | G19: =E19*C19 -> 72 | H19: 2 | I19: =8/(G19/3600)*H19 -> 800 | J19: =I19*3*0.8 -> 1920 | N19: =N18 -> -0.020771033
A20: Teton | B20: Wire welding | C20: 4 | E20: 20 | G20: =C20*E20 -> 80 | H20: 1 | I20: =8/(G20/3600)*H20 -> 360 | J20: =I20*3*0.8 -> 864 | K20: =MIN(J20:J21) -> 864 | L20: =K20*26 -> 22464
B21: Metal welding | C21: 4 | E21: 15 | G21: =C21*E21 -> 60 | H21: 1 | I21: =8/(G21/3600)*H21 -> 480 | J21: =I21*3*0.8 -> 1152
A22: Meta-Facebook | B22: Metal welding | C22: 2 | E22: 13 | G22: =E22*C22 -> 26 | H22: 1 | I22: =8/(G22/3600)*H22 -> 1107.6923 | J22: =I22*3*0.8 -> 2658.4615 | K22: =MIN(J22:J23) -> 2658.4615 | L22: =K22*26 -> 69120
B23: 5 Wire welding | C23: 2 | E23: 25 | G23: =E23*C23 -> 50 | H23: 2 | I23: =8/(G23/3600)*H23 -> 1152 | J23: =I23*3*0.8 -> 2764.8
A24: Tesla | B24: Wire welding | C24: 1 | E24: 33 | G24: =E24*C24 -> 33 | H24: 1 | I24: =8/(G24/3600)*H24 -> 872.72727 | J24: =I24*3*0.8 -> 2094.5455 | K24: =J24 -> 2094.5455 | L24: =K24*26 -> 54458.182
A26: Total | H26: =SUM(H17:H25) -> 12 | L26: =SUM(L17:L25) -> 195962.18
A28: Capacity by Q2-2025
A29: BK300 | B29: Weld type | C29: Qty/FG | D29: Old-CT | E29: New-CT | F29: CT Improvement | G29: Total CT | H29: No: of M/c | I29: O/t-Shift | J29: O/t-Day | K29: FG/Day | L29: Monthly capacity | M29: Remark | N29: June -Plan
B30: Metal welding | C30: 4 | D30: 12 | E30: 9 | F30: =(D30-E30)/D30 -> 0.25 | G30: =E30*C30 -> 36 | H30: 2.5 | I30: =8/(G30/3600)*H30 -> 2000 | J30: =I30*3*0.8 -> 4800 | K30: =MIN(J30:J32) -> 2541.1765 | L30: =K30*30 -> 76235.294 | M30: Machine running 24x7 | N30: 70000
B31: Wire welding | C31: 4 | D31: 25 | E31: 17 | F31: =(D31-E31)/D31 -> 0.32 | G31: =E31*C31 -> 68 | H31: 2.5 | I31: =8/(G31/3600)*H31 -> 1058.8235 | J31: =I31*3*0.8 -> 2541.1765
B32: Z welding | C32: 4 | D32: 18 | E32: 17 | F32: =(D32-E32)/D32 -> 0.055555556 | G32: =E32*C32 -> 68 | H32: 3 | I32: =8/(G32/3600)*H32 -> 1270.5882 | J32: =I32*3*0.8 -> 3049.4118
A33: Meta | B33: Metal welding | C33: 2 | D33: 12 | E33: 9 | F33: =(D33-E33)/D33 -> 0.25 | G33: =E33*C33 -> 18 | H33: 1 | I33: =8/(G33/3600)*H33 -> 1600 | J33: =I33*3*0.75 -> 3600 | K33: =MIN(J33:J34) -> 1800 | L33: =K33*30 -> 54000 | M33: Machine sharing for Meta and 438LF.Machine running 24x7 | N33: 53400
B34: 5 Wire welding | C34: 2 | D34: 18 | E34: 18 | F34: =(D34-E34)/D34 -> 0 | G34: =E34*C34 -> 36 | H34: 1 | I34: =8/(G34/3600)*H34 -> 800 | J34: =I34*3*0.75 -> 1800
B35: Wire welding | C35: 1 | E35: 33 | G35: =E35*C35 -> 33 | I35: =8/(G35/3600)*H35 -> 0 | J35: =I35*3*0.8 -> 0 | K35: =J35 -> 0 | L35: =K35*25 -> 0 | M35: Starting from Mar-13th after completion of Meta-2000/day. | N35: 31680 | O35: =N35/3600 -> 8.8
A37: Teton 2 | B37: LP welding | C37: 16 | D37: 16 | E37: 12 | F37: =(D37-E37)/D37 -> 0.25 | G37: =E37*C37 -> 192 | H37: 4 | I37: =8/(G37/3600)*H37 -> 600 | J37: =I37*3*0.8 -> 1440 | K37: =MIN(J37:J38) -> 1440 | L37: =K37*30 -> 43200 | M37: Machine running 24x7 | N37: 40000
B38: HP welding | C38: 4 | D38: 53 | E38: 22 | F38: =(D38-E38)/D38 -> 0.58490566 | G38: =E38*C38 -> 88 | H38: 2 | I38: =8/(G38/3600)*H38 -> 654.54545 | J38: =I38*3*0.8 -> 1570.9091
A39: Tesla | B39: Wire to metal welding | C39: 1 | E39: 15 | F39: =(D39-E39)/D39 -> #DIV/0! | G39: =E39*C39 -> 15 | H39: 0.5 | I39: =8/(G39/3600)*H39 -> 960 | J39: =I39*3*0.8 -> 2304 | K39: =MIN(J39:J40) -> 1728 | L39: =K39*26 -> 44928 | M39: Machine sharing for Tesla,1QLF,NPD | N39: 32000
B40: Wire to metal welding | C40: 1 | E40: 20 | F40: =(D40-E40)/D40 -> #DIV/0! | G40: =E40*C40 -> 20 | H40: 0.5 | I40: =8/(G40/3600)*H40 -> 720 | J40: =I40*3*0.8 -> 1728
A41: Total | H41: =SUM(H30:H40) -> 17 | L41: =SUM(L30:L40) -> 218363.29
A43: Additional points
A44: 17 Welding machine considered
A45: All machine need to run 24x7
A51: Capacity by Q2-2025
A52: BK300 | B52: Weld type | C52: Qty/FG | D52: Old-ct | E52: CT | F52: CT Improvement | G52: Total CT | H52: No: of M/c | I52: O/t-Shift | J52: O/t-Day | K52: FG/Day | L52: Monthly capacity
...

Sheet Sheet4
A3: Row Labels | B3: Sum of Quantity
A4: 552PWBVR | B4: 96426
A5: Grand Total | B5: 96426
H6: PB+RAH | I6: =60000+40000 -> 100000 | J6: =I6/4500 -> 22.222222
H7: PB+VTR | I7: 15974 | J7: =I7/6000 -> 2.6623333
G8: 1 | H8: PBRAH | I8: =30000+111496 -> 141496 | J8: =I8/4500 -> 31.443556
G9: 1 | H9: PBVTR | I9: 96426 | J9: =I9/6000 -> 16.071
H10: PBRAR | I10: 30000

Sheet Sheet2
A3: Row Labels | B3: Sum of Quantity | C3: Sum of Value
A4: 346PB+RH | B4: 55906 | C4: 91.305192
A5: 346PB+VR | B5: 12446 | C5: 21.281308
A6: 352ACIPC | B6: 2464 | C6: 26.498214
A7: 355BK100 | B7: 58000 | C7: 220.51281
A8: 355BK300 | B8: 70000 | C8: 944.59726
A9: 355BK50C | B9: 27650 | C9: 294.5742
A10: 355BRKCA | B10: 81804 | C10: 321.73705
A11: 355METCA | B11: 3710 | C11: 85
A12: 355TSLCA | B12: 22040 | C12: 122.5776
A13: 355TT2CA | B13: 40000 | C13: 2059.2025
A14: 356ACICB | B14: 10000 | C14: 235.25216
A15: 356MC54I | B15: 5150 | C15: 2.1453156
... A33: 612FIT30 | B33: 2980 | C33: 16.395457
A34: (blank) | C34: 7230.8795
A35: Grand Total | B35: 1526794 | C35: 14461.759

Sheet PB
H1: =#REF!*2 -> #REF!
G2: Night Shift | H2: 8
G3: Total | H3: =H2+H1 -> #REF!
H4: =ROUNDUP(H3*0.12,0) -> #REF!
C5: ='PN-workout file'!#REF!+'PN-workout file'!#REF!+'PN-workout file'!#REF!+'PN-workout file'!#REF!+'PN-workout file'!N15+'PN-workout file'!P15+'PN-workout file'!#REF!+'PN-workout file'!#REF!+'PN-workout file'!N14+'PN-workout file'!P14+'PN-workout file'!N25+'PN-workout file'!P25+'PN-workout file'!#REF!+'PN-workout file'!#REF!+'PN-workout file'!N22+'PN-workout file'!P22+'PN-workout file'!#REF!+'PN-workout file'!N20+'PN-workout file'!P20+'PN-workout file'!N19+'PN-workout file'!P19+'PN-workout file'!P18+'PN-workout file'!N18+'PN-workout file'!N9+'PN-workout file'!P9+'PN-workout file'!N8+PB!A7 -> #REF! | H5: =H3+H4 -> #REF!
A7: Power Blade
A8: Sl. No. | B8: Machine | C8: Machine Operator | D8: Quality Control | E8: Grid Checker | F8: Vision System | G8: Packing | H8: Cover Assembly | I8: Shifts Operated | J8: Required HC | K8: Leave Reserve @ 10% | L8: Sunday working | M8: Total
A9: 1 | B9: PB + RAH | C9: 2 | D9: 1 | E9: 1 | F9: 1 | G9: 1 | H9: 2 | I9: 3 | J9: =(SUM(C9:F9)+G9+H9)*I9 -> 24 | K9: =J9*0.12 -> 2.88 | L9: =J9/6 -> 4 | M9: =J9+K9+L9 -> 30.88
A10: 2 | B10: PB RAH | C10: 2 | D10: 1 | E10: 1 | F10: 1 | I10: 3 | J10: =(SUM(C10:F10)+G9+H9)*I10 -> 24 | K10: =J10*0.12 -> 2.88 | L10: 0 | M10: =J10+K10+L10 -> 26.88
A11: 3 | B11: PB + VTR | C11: 2 | D11: 1 | E11: 1 | F11: 1 | G11: 1 | I11: 3 | J11: =(SUM(C11:F11)+G11+H9)*I11 -> 24 | K11: =J11*0.12 -> 2.88 | L11: =J11/6 -> 4 | M11: =J11+K11+L11 -> 30.88
A12: 4 | B12: PB VTR | C12: 2 | D12: 1 | E12: 1 | F12: 1 | I12: 2 | J12: =(SUM(C12:F12)+G9+H9)*I12 -> 16 | K12: =J12*0.12 -> 1.92 | L12: 0 | M12: =J12+K12+L12 -> 17.92
A13: 5 | B13: PBU RAR | C13: 2 | D13: 1 | E13: 1 | F13: 1 | I13: 3 | J13: =(SUM(C13:F13)+G10+H10)*I13 -> 15 | K13: =J13*0.12 -> 1.8 | L13: 0 | M13: =J13+K13+L13 -> 16.8
A14: 6 | B14: Airmax | C14: 6
A15: Total HC for PB | M15: =SUM(M9:M14)+C14 -> 129.36
O25: Power Blade
O26: Sl. No. | P26: Machine | Q26: Machine Operator | R26: Quality Control | S26: Grid Checker | T26: Vision System | U26: Packing | V26: Cover Assembly | W26: Shifts Operated | X26: Additional personnel for night Shift | Y26: Leave Reserve @ 10% | Z26: Remarks | AB26: Sunday working
O27: 1 | P27: PB + RAH | Q27: 2 | R27: 1 | S27: 1 | T27: 1 | U27: 1 | V27: 2 | W27: 2 | X27: =SUM(Q27:T28)+Q30+R30+S30+T30+U27+U29+V27 -> 19 | Y27: =ROUNDUP((SUM(Q27:V31)*2+X27)*0.12,0) -> 9
O28: 2 | P28: PB RAH | Q28: 2 | R28: 1 | S28: 1 | T28: 1
O29: 3 | P29: PB + VTR | Q29: 2 | R29: 1 | S29: 1 | T29: 1 | U29: 1 | W29: 1
O30: 4 | P30: PB VTR | Q30: 2 | R30: 1 | S30: 1 | T30: 1 | W30: 3
O31: 5 | P31: PB RAR
O32: Total HC for PB | AA32: =SUM(Q27:V30)*W27+X27+Y27+Q31 -> 76

Sheet PN-workout file (2)
A1: Item Number | B1: Description | C1: Qty. | D1: CT | H1: Hrs. | L1: HC/ Day | M1: Sunday working-HC | N1: LR @12% | P1: Remarks
D2: MA | E2: MA | F2: I&P | G2: Total | H2: MA | I2: I&P | J2: Total | K2: Target/day | O2: Total HC | Q2: Wire cutting | R2: Cropping | S2: Welding | T2: Sum
A3: 10130664-9RF438LF | B3: Meta/Amazon | C3: 28980 | D3: =0.18-(T3) -> 0.1425 | E3: =0.18 -> 0.18 | F3: 0.03125 | G3: =D3+F3 -> 0.17375 | H3: =E3*C3 -> 5216.4 | I3: =F3*C3 -> 905.625 | J3: =SUM(H3:I3) -> 6122.025 | K3: =C3/$X$5 -> 1207.5 | L3: =C3*G3/$X$5/7.05/$X$4 -> 33.817396 | N3: =L3*0.12 -> 4.0580875 | O3: =L3+M3+N3 -> 37.875484 | Q3: =50/3600 -> 0.013888889 | R3: =20/3600 -> 0.0055555556 | S3: =65/3600 -> 0.018055556 | T3: =SUM(Q3:S3) -> 0.0375
A4: 10158287-9RF034HF | B4: BK300 | C4: 47660 | D4: =(0.225)-(T4) -> 0.16361111 | E4: =0.225 -> 0.225 | F4: =0.0413888*0.8 -> 0.03311104 | G4: =D4+F4 -> 0.19672215 | H4: =E4*C4 -> 10723.5 | I4: =F4*C4 -> 1578.0722 | J4: =SUM(H4:I4) -> 12301.572 | K4: =C4/$X$5 -> 1985.8333 | L4: =C4*G4/$X$5/7.05/$X$4 -> 62.968634 | N4: =L4*0.12 -> 7.5562361 | O4: =L4+M4+N4 -> 70.52487 | Q4: =31/3600 -> 0.0086111111 | R4: =10/3600 -> 0.0027777778 | S4: =180/3600 -> 0.05 | T4: =SUM(Q4:S4) -> 0.061388889 | W4: DL % | X4: 0.88
A5: 10162405-1S2009LF | B5: BK50 | C5: 14700 | D5: 0.099 | E5: =0.1 -> 0.1 | F5: 0.00807 | G5: =D5+F5 -> 0.10707 | H5: =E5*C5 -> 1470 | I5: =F5*C5 -> 118.629 | J5: =SUM(H5:I5) -> 1588.629 | K5: =C5/$X$5 -> 612.5 | L5: =C5*G5/$X$5/7.05/$X$4 -> 10.57066 | N5: =(L5*0.12) -> 1.2684792 | O5: =L5+M5+N5 -> 11.839139 | W5: Wokring days | X5: 24
A6: RPS07007X9-004 (20 Amps) | B6: ORV3 | C6: =5600 -> 5600 | D6: =1000/3600 -> 0.27777778 | F6: =300/3600 -> 0.083333333 | G6: =D6+F6 -> 0.36111111 | H6: =D6*C6 -> 1555.5556 | I6: =F6*C6 -> 466.66667 | J6: =SUM(H6:I6) -> 2022.2222 | K6: =C6/$X$5 -> 233.33333 | L6: =C6*G6/$X$5/7.05/$X$4 -> 13.581441 | N6: =L6*0.12 -> 1.6297729 | O6: =L6+M6+N6 -> 15.211214
A7: 10165987-101LF | B7: socket body(Z4/Z2) | C7: 263000 | D7: 0.0079861 | F7: 0.0053833 | G7: =SUM(D7:F7) -> 0.0133694 | H7: =D7*C7 -> 2100.3443 | I7: =F7*C7 -> 1415.8079 | J7: =SUM(H7:I7) -> 3516.1522 | K7: =C7/$X$5 -> 10958.333 | L7: =C7*G7/$X$5/7.05/$X$4 -> 23.61482 | N7: =L7*0.12 -> 2.8337784 | O7: =L7+M7+N7 -> 26.448598
A8: 10166013-101LF | B8: Microsoft | D8: 0.0069861 | F8: 0.0009056 | G8: =SUM(D8:F8) -> 0.0078917 | H8: =D8*C8 -> 0 | I8: =F8*C8 -> 0 | J8: =SUM(H8:I8) -> 0 | K8: =C8/$X$5 -> 0 | L8: =C8*G8/$X$5/7.05/$X$4 -> 0 | N8: =ROUNDUP(L8*0.12,0) -> 0 | O8: =L8+M8+N8 -> 0
A9: 10157266-001LF | B9: BK200 XP | D9: 0.01818 | F9: 0.00964 | G9: =SUM(D9:F9) -> 0.02782 | H9: =D9*C9 -> 0 | I9: =F9*C9 -> 0 | J9: =SUM(H9:I9) -> 0 | K9: =C9/$X$5 -> 0 | L9: =C9*G9/$X$5/7.05/$X$4 -> 0 | N9: =L9*0.12 -> 0 | O9: =L9+M9+N9 -> 0
A10: 10130664-9D0354LF | B10: TESLA | C10: 16560 | D10: =0.17-T10 -> 0.15194444 | E10: 0.17 | F10: 0.03 | G10: =D10+F10 -> 0.18194444 | H10: =E10*C10 -> 2815.2 | I10: =F10*C10 -> 496.8 | J10: =SUM(H10:I10) -> 3312 | K10: =C10/$X$5 -> 690 | L10: =C10*G10/$X$5/7.05/$X$4 -> 20.235601 | N10: =L10*0.12 -> 2.4282721 | O10: =L10+M10+N10 -> 22.663873 | Q10: =15/3600 -> 0.0041666667 | R10: =10/3600 -> 0.0027777778 | S10: =40/3600 -> 0.011111111 | T10: =SUM(Q10:S10) -> 0.018055556
A11: 10170425-1RF033LF | B11: TETON2 | C11: 31700 | D11: =0.365-T11 -> 0.22888889 | E11: 0.395 | F11: 0.0611 | G11: =D11+F11 -> 0.28998889 | H11: =E11*C11 -> 12521.5 | I11: =F11*C11 -> 1936.87 | J11: =SUM(H11:I11) -> 14458.37 | K11: =C11/$X$5 -> 1320.8333 | L11: =C11*G11/$X$5/7.05/$X$4 -> 61.738715 | N11: =L11*0.12 -> 7.4086459 | O11: =L11+M11+N11 -> 69.147361 | Q11: =90/3600 -> 0.025 | R11: =100/3600 -> 0.027777778 | S11: =300/3600 -> 0.083333333 | T11: =SUM(Q11:S11) -> 0.13611111
A12: 10174780-001LF | B12: ET30 | D12: 0.016 | F12: 0.005 | G12: =SUM(D12:F12) -> 0.021 | H12: =D12*C12 -> 0 | I12: =F12*C12 -> 0 | J12: =SUM(H12:I12) -> 0 | K12: =C12/$X$5 -> 0 | L12: =C12*G12/$X$5/7.05/$X$4 -> 0 | N12: =L12*0.12 -> 0 | O12: =L12+M12+N12 -> 0
B13: FIT30 | D13: 0.0472222 | F13: 0.0107639 | G13: =SUM(D13:F13) -> 0.0579861 | H13: =D13*C13 -> 0 | I13: =F13*C13 -> 0 | J13: =SUM(H13:I13) -> 0 | K13: =C13/$X$5 -> 0 | L13: =C13*G13/$X$5/7.05/$X$4 -> 0 | N13: =L13*0.12 -> 0 | O13: =L13+M13+N13 -> 0
A14: PWRMRA028 | B14: ET20 | C14: =14400+4000 -> 18400 | D14: 0.0414028 | F14: 0.0079861 | G14: =SUM(D14:F14) -> 0.0493889 | H14: =D14*C14 -> 761.81152 | I14: =F14*C14 -> 146.94424 | J14: =SUM(H14:I14) -> 908.75576 | K14: =C14/$X$5 -> 766.66667 | L14: =C14*G14/$X$5/7.05/$X$4 -> 6.103292 | N14: =L14*0.12 -> 0.73239504 | O14: =L14+M14+N14 -> 6.835687
B15: BK350 | C15: 123000 | D15: 0.0100694 | F15: 0.0041667 | G15: =SUM(D15:F15) -> 0.0142361 | H15: =D15*C15 -> 1238.5362 | I15: =F15*C15 -> 512.5041 | J15: =SUM(H15:I15) -> 1751.0403 | K15: =C15/$X$5 -> 5125 | L15: =C15*G15/$X$5/7.05/$X$4 -> 11.760157 | N15: =L15*0.12 -> 1.4112188 | O15: =L15+M15+N15 -> 13.171376
A16: 10170775-170502 | B16: ORV3 CONNECTOR | C16: 20720 | D16: 0.05 | F16: 0.009 | G16: =SUM(D16:F16) -> 0.059 | H16: =D16*C16 -> 1036 | I16: =F16*C16 -> 186.48 | J16: =SUM(H16:I16) -> 1222.48 | K16: =C16/$X$5 -> 863.33333 | L16: =C16*G16/$X$5/7.05/$X$4 -> 8.2102944 | N16: =L16*0.12 -> 0.98523533 | O16: =L16+M16+N16 -> 9.1955298
A17: 10182948-Q50001 | B17: ACWHIP Qseries | D17: 0.56 | F17: 0.14 | G17: =SUM(D17:F17) -> 0.7 | H17: =D17*C17 -> 0 | I17: =F17*C17 -> 0 | J17: =SUM(H17:I17) -> 0 | K17: =C17/$X$5 -> 0 | L17: =C17*G17/$X$5/7.05/$X$4 -> 0 | N17: =L17*0.12 -> 0 | O17: =L17+M17+N17 -> 0
A18: 10178161-C7A303 (30 Amps) | B18: ORV3 | C18: =21648 -> 21648 | D18: =1400/3600 -> 0.38888889 | F18: 0.145 | G18: =SUM(D18:F18) -> 0.53388889 | H18: =D18*C18 -> 8418.6667 | I18: =F18*C18 -> 3138.96 | J18: =SUM(H18:I18) -> 11557.627 | K18: =C18/$X$5 -> 902 | L18: =C18*G18/$X$5/7.05/$X$4 -> 77.622143 | M18: =L18*(1/6) -> 12.937024 | N18: =(L18+M18)*0.12 -> 10.8671 | O18: =L18+M18+N18 -> 101.42627
A19: 10170827-07P002 | B19: ORV3 | C19: 0 | D19: 0.08 | F19: 0.03 | G19: =SUM(D19:F19) -> 0.11 | H19: =D19*C19 -> 0 | I19: =F19*C19 -> 0 | J19: =SUM(H19:I19) -> 0 | K19: =C19/$X$5 -> 0 | L19: =C19*G19/$X$5/7.05/$X$4 -> 0 | N19: =L19*0.12 -> 0 | O19: =L19+M19+N19 -> 0
A20: 10180876-E7C01 | B20: ORV3 | D20: 0.516 | F20: 0.1453 | G20: =SUM(D20:F20) -> 0.6613 | H20: =D20*C20 -> 0 | I20: =F20*C20 -> 0 | J20: =SUM(H20:I20) -> 0 | K20: =C20/$X$5 -> 0 | L20: =C20*G20/$X$5/7.05/$X$4 -> 0 | M20: =L20*(1/6) -> 0 | N20: =L20*0.12 -> 0 | O20: =L20+M20+N20 -> 0
A21: 10188304-054F01 | B21: ORV3-100A | C21: 1000 | D21: 0.42 | F21: =500/3600 -> 0.13888889 | G21: =SUM(D21:F21) -> 0.55888889 | H21: =D21*C21 -> 420 | I21: =F21*C21 -> 138.88889 | J21: =SUM(H21:I21) -> 558.88889 | K21: =C21/$X$5 -> 41.666667 | L21: =C21*G21/$X$5/7.05/$X$4 -> 3.7535521 | N21: =L21*0.12 -> 0.45042625 | O21: =L21+M21+N21 -> 4.2039783
A22: 10182476-71A801 | B22: ORV3 | C22: 16000 | D22: 0.3911 | F22: 0.0427 | G22: =SUM(D22:F22) -> 0.4338 | H22: =D22*C22 -> 6257.6 | I22: =F22*C22 -> 683.2 | J22: =SUM(H22:I22) -> 6940.8 | K22: =C22/$X$5 -> 666.66667 | L22: =C22*G22/$X$5/7.05/$X$4 -> 46.615087 | N22: =L22*0.12 -> 5.5938104 | O22: =L22+M22+N22 -> 52.208897
A23: 1018106X-K7000X (K series) | B23: ORV3 | C23: 19000 | D23: =1200/3600 -> 0.33333333 | F23: =280/3600 -> 0.077777778 | G23: =SUM(D23:F23) -> 0.41111111 | H23: =D23*C23 -> 6333.3333 | I23: =F23*C23 -> 1477.7778 | J23: =SUM(H23:I23) -> 7811.1111 | K23: =C23/$X$5 -> 791.66667 | L23: =C23*G23/$X$5/7.05/$X$4 -> 52.460181 | M23: 9 | N23: =(L23+M23)*0.12 -> 7.3752217 | O23: =L23+M23+N23 -> 68.835403
A24: 10176873-19-F140LF | B24: ORV3-60A | C24: 9284 | D24: =3300/3600 -> 0.91666667 | F24: =500/3600 -> 0.13888889 | G24: =SUM(D24:F24) -> 1.0555556 | H24: =D24*C24 -> 8510.3333 | I24: =F24*C24 -> 1289.4444 | J24: =SUM(H24:I24) -> 9799.7778 | K24: =C24/$X$5 -> 386.83333 | L24: =C24*G24/$X$5/7.05/$X$4 -> 65.81626 | M24: =L24*(1/6) -> 10.969377 | N24: =L24*0.12 -> 7.8979511 | O24: =L24+M24+N24 -> 84.683587
A25: 10176873-09-F044LF | B25: ORV3-60A | D25: 0.799 | F25: 0.319 | G25: =SUM(D25:F25) -> 1.118 | H25: =D25*C25 -> 0 | I25: =F25*C25 -> 0 | J25: =SUM(H25:I25) -> 0 | K25: =C25/$X$5 -> 0 | L25: =C25*G25/$X$5/7.05/$X$4 -> 0 | N25: =L25*0.12 -> 0 | O25: =L25+M25+N25 -> 0
A26: 10176873-37-F247LF | B26: ORV3-60A | D26: 0.7 | F26: 0.32 | G26: =SUM(D26:F26) -> 1.02 | H26: =D26*C26 -> 0 | I26: =F26*C26 -> 0 | J26: =SUM(H26:I26) -> 0 | K26: =C26/$X$5 -> 0 | L26: =C26*G26/$X$5/7.05/$X$4 -> 0 | N26: =L26*0.12 -> 0 | O26: =L26+M26+N26 -> 0
A27: 10176873-18-F126LF | B27: ORV3-60A | D27: 0.61 | F27: 0.31 | G27: =SUM(D27:F27) -> 0.92 | H27: =D27*C27 -> 0 | I27: =F27*C27 -> 0 | J27: =SUM(H27:I27) -> 0 | K27: =C27/$X$5 -> 0 | L27: =C27*G27/$X$5/7.05/$X$4 -> 0 | N27: =L27*0.12 -> 0 | O27: =L27+M27+N27 -> 0
A28: 10170827-07P003 | B28: ORV3-Connector | C28: 0 | D28: 0.08 | F28: 0.032 | G28: =SUM(D28:F28) -> 0.112 | H28: =D28*C28 -> 0 | I28: =F28*C28 -> 0 | J28: =SUM(H28:I28) -> 0 | K28: =C28/$X$5 -> 0 | L28: =C28*G28/$X$5/7.05/$X$4 -> 0 | N28: =L28*0.12 -> 0 | O28: =L28+M28+N28 -> 0
A29: 10146534-1EP063LF | B29: BK 100 Cable | C29: 18550 | D29: =0.065-T29 -> 0.035833333 | E29: 0.065 | F29: 0.022 | G29: =D29+F29 -> 0.057833333 | H29: =E29*C29 -> 1205.75 | I29: =F29*C29 -> 408.1 | J29: =SUM(H29:I29) -> 1613.85 | K29: =C29/$X$5 -> 772.91667 | L29: =C29*G29/$X$5/7.05/$X$4 -> 7.205085 | N29: =L29*0.12 -> 0.8646102 | O29: =L29+M29+N29 -> 8.0696952 | Q29: =15/3600 -> 0.0041666667 | R29: =10/3600 -> 0.0027777778 | S29: =2*40/3600 -> 0.022222222 | T29: =SUM(Q29:S29) -> 0.029166667
A30: 10172541-001LF | B30: BK25 | D30: 0.0409 | F30: 0.0065 | G30: =SUM(D30:F30) -> 0.0474 | H30: =D30*C30 -> 0 | I30: =F30*C30 -> 0 | J30: =SUM(H30:I30) -> 0 | K30: =C30/$X$5 -> 0 | L30: =C30*G30/$X$5/7.05/$X$4 -> 0 | N30: =L30*0.12 -> 0 | O30: =L30+M30+N30 -> 0
A31: 10174690-1UF026LF | B31: Oracle | D31: 0.295472 | F31: 0.0277778 | G31: =SUM(D31:F31) -> 0.3232498 | H31: =D31*C31 -> 0 | I31: =F31*C31 -> 0 | J31: =SUM(H31:I31) -> 0 | K31: =C31/$X$5 -> 0 | L31: =C31*G31/$X$5/7.05/$X$4 -> 0 | N31: =L31*0.12 -> 0 | O31: =L31+M31+N31 -> 0 | V31: Power Blade - Support. Staff
A32: 10170820-001LF | B32: IPC Battery | C32: 21000 | D32: 0.004 | F32: 0.0025 | G32: =SUM(D32:F32) -> 0.0065 | H32: =D32*C32 -> 84 | I32: =F32*C32 -> 52.5 | J32: =SUM(H32:I32) -> 136.5 | K32: =C32/$X$5 -> 875 | L32: =C32*G32/$X$5/7.05/$X$4 -> 0.91674726 | N32: =L32*0.12 -> 0.11000967 | O32: =L32+M32+N32 -> 1.0267569
A33: 10170425-9B0040LF | B33: BK350 | C33: 25902 | D33: 0.145 | F33: 0.008 | G33: =D33+F33 -> 0.153 | H33: =D33*C33 -> 3755.79 | I33: =F33*C33 -> 207.216 | J33: =SUM(H33:I33) -> 3963.006 | K33: =C33/$X$5 -> 1079.25 | L33: =C33*G33/$X$5/7.05/$X$4 -> 26.615933 | N33: =L33*0.12 -> 3.193912 | O33: =L33+M33+N33 -> 29.809845
A34: HPG36P14SRT051TH07 | B34: EEX | C34: =12200+7820 -> 20020 | D34: 0.066 | F34: 0.013 | G34: =SUM(D34:F34) -> 0.079 | H34: =D34*C34 -> 1321.32 | I34: =F34*C34 -> 260.26 | J34: =SUM(H34:I34) -> 1581.58 | K34: =C34/$X$5 -> 834.16667 | L34: =C34*G34/$X$5/7.05/$X$4 -> 10.622045 | N34: =L34*0.12 -> 1.2746454 | O34: =L34+M34+N34 -> 11.89669
A35: 10173947-100012LF | B35: 48V Connector | C35: 48500 | D35: 0.0104167 | F35: 0.0048 | G35: =SUM(D35:F35) -> 0.0152167 | H35: =D35*C35 -> 505.20995 | I35: =F35*C35 -> 232.8 | J35: =SUM(H35:I35) -> 738.00995 | K35: =C35/$X$5 -> 2020.8333 | L35: =C35*G35/$X$5/7.05/$X$4 -> 4.9565465 | N35: =L35*0.12 -> 0.59478558 | O35: =L35+M35+N35 -> 5.5513321
A36: 10174690-1UF011LF | B36: BK220 I/O Cable Assembly | C36: 2600 | D36: =0.24-T36 -> 0.19333333 | E36: 0.24 | F36: 0.02 | G36: =D36+F36 -> 0.21333333 | H36: =E36*C36 -> 624 | I36: =F36*C36 -> 52 | J36: =SUM(H36:I36) -> 676 | K36: =C36/$X$5 -> 108.33333 | L36: =C36*G36/$X$5/7.05/$X$4 -> 3.7251952 | N36: =L36*0.12 -> 0.44702343 | O36: =L36+M36+N36 -> 4.1722186 | Q36: =36/3600 -> 0.01 | S36: =22*6/3600 -> 0.036666667 | T36: =SUM(Q36:S36) -> 0.046666667
A37: 10146534-9B0001LF | B37: BK ZOID | C37: 621 | D37: 0.322 | E37: 0.322 | F37: 0.04 | G37: =D37+F37 -> 0.362 | H37: =E37*C37 -> 199.962 | I37: =F37*C37 -> 24.84 | J37: =SUM(H37:I37) -> 224.802 | K37: =C37/$X$5 -> 25.875 | L37: =C37*G37/$X$5/7.05/$X$4 -> 1.5097921 | N37: =L37*0.12 -> 0.18117505 | O37: =L37+M37+N37 -> 1.6909671
A38: 10170744-9D0001LF | B38: BK250 | C38: 10000 | D38: =0.26-T38 -> 0.20111111 | E38: 0.28 | F38: 0.03 | G38: =D38+F38 -> 0.23111111 | H38: =E38*C38 -> 2800 | I38: =F38*C38 -> 300 | J38: =SUM(H38:I38) -> 3100 | K38: =C38/$X$5 -> 416.66667 | L38: =C38*G38/$X$5/7.05/$X$4 -> 15.521647 | N38: =L38*0.12 -> 1.8625976 | O38: =L38+M38+N38 -> 17.384244 | Q38: =36/3600 -> 0.01 | S38: =22*8/3600 -> 0.048888889 | T38: =SUM(Q38:S38) -> 0.058888889
A39: 10174690-1WF149LF | B39: BK220 | C39: 1060 | D39: =0.176-T39 -> 0.11711111 | E39: 0.176 | F39: 0.029 | G39: =D39+F39 -> 0.14611111 | H39: =E39*C39 -> 186.56 | I39: =F39*C39 -> 30.74 | J39: =SUM(H39:I39) -> 217.3 | K39: =C39/$X$5 -> 44.166667 | L39: =C39*G39/$X$5/7.05/$X$4 -> 1.0401742 | N39: =L39*0.12 -> 0.1248209 | O39: =L39+M39+N39 -> 1.1649951 | Q39: =36/3600 -> 0.01 | S39: =22*8/3600 -> 0.048888889 | T39: =SUM(Q39:S39) -> 0.058888889
A40: C10176572-B000R | B40: CSD | C40: 10000 | D40: =228/3600 -> 0.063333333 | F40: =110/3600 -> 0.030555556 | G40: =SUM(D40:F40) -> 0.093888889 | H40: =D40*C40 -> 633.33333 | I40: =F40*C40 -> 305.55556 | J40: =SUM(H40:I40) -> 938.88889 | K40: =C40/$X$5 -> 416.66667 | L40: =C40*G40/$X$5/7.05/$X$4 -> 6.305669 | N40: =L40*0.12 -> 0.75668028 | O40: =L40+M40+N40 -> 7.0623493
...

Sheet NPD crew details
F5: NPD Crew Details
F6: Team | G6: Nos
F7: QA/QC | G7: 19
F8: Technisian | G8: 1
F9: DL-Assembly | G9: 61
F10: Process Technisian | G10: 2
F11: Molding | G11: 3
F12: Stores | G12: 3
F13: NAPS-Lead | G13: 3
F15: Total | G15: =SUM(G7:G13) -> 92

Sheet Sheet6
D3: Assembly Lines | E3: HC Allocated by IE | F3: Present HC on Shop floor | G3: Gap
C4: Manufacturing | D4: Crew required for BK cable Assembly | E4: =(439.156635800463+32)*0.88 -> 414.61784 | H4: 0.88
D5: Crew required for ACWHIP | E5: =(400.584717386632+19)*0.88 -> 369.23455
D6: Crew required for Connector | E6: =(196.188319033121+26)*0.88 -> 195.52572
D7: Training crew | E7: 44
D8: Crew required for EV | E8: 198.88
D9: Total Crew for Manufacturing | E9: =SUM(E4:E8) -> 1222.2581 | F9: 1208 | G9: =F9-E9 -> -14.258112

Sheet Plan-Jan
A2: HPL | B2: Item group | C2: Row Labels | D2: Description | E2: Jan Plan | F2: Additional Expected
A3: 346 | B3: 346PB+RH | C3: 10106116-4000002LF | D3: Connector,PB+RH | E3: 2970
A4: 346 | B4: 346PB+RH | C4: 10106116-6000001LF | D4: Connector,PB+RH | E4: 1056
A5: 346 | B5: 346PB+RH | C5: 10106116-8000K01LF | D5: PwrBlade+ RAH STB | E5: 396
A6: 552 | B6: 552PB+VR | C6: 10106122-5004001LF | D6: PwrBlade+ VTR | E6: 2880
A7: 552 | B7: 552PB+RH | C7: 10106124-4006005LF | D7: PB+ RAH STB | E7: 792
A8: 346 | B8: 346PB+RH | C8: 10106124-8005003LF | D8: PwrBlade+ RAH | E8: 37790
A9: 346 | B9: 346PB+RH | C9: 10106124-9000002LF | D9: PwrBlade+ RAH STB | E9: 264
A10: 346 | B10: 346PB+RH | C10: 10106124-E000K01LF | D10: Connector,PB+RH | E10: 1056
A11: 346 | B11: 346PB+RH | C11: 10106124-E008001LF | D11: PwrBlade+ RAH | E11: 10032
A12: 346 | B12: 346PB+RH | C12: 10106124-F005K01LF | D12: PwrBlade+ RAH STB | E12: 5280
A13: 346 | B13: 346PB+VR | C13: 10106131-2202001LF | D13: PwrBlade+ VR PF | E13: 6264
A14: 346 | B14: 346PB+VR | C14: 10106131-4004001LF | D14: PwrBlade+ VR PF | E14: 11160
... A70: 519 | B70: 519B5080 | C70: 10169634-S01LF | D70: PLATED SENSOR CONTACTS | E70: 11679
A71: 352 | B71: 352ACIPC | C71: 10170775-170501 | D71: OCP AC_IN RKEY R-MALE | E71: 3472 | F71: 2240
A72: 352 | B72: 352ACIPC | C72: 10170775-170502 | D72: OCP AC_IN RKEY L-MALE | E72: 3920 | F72: 2240
A73: 329 | B73: 329IPC | C73: 10170818-S01LF | D73: IPC-S75/M50 10/12HDCT | E73: 81200
